[2024-06-01T00:57:44.130+0000] {scheduler_job_runner.py:1575} WARNING - Marking task instance <TaskInstance: crawl_stock_data.crawl_stock_price_task manual__2024-06-01T00:46:54.511401+00:00 [queued]> stuck in queued as failed. If the task instance has available retries, it will be retried.
[2024-06-01T00:57:45.094+0000] {scheduler_job_runner.py:781} ERROR - Executor reports task instance <TaskInstance: crawl_stock_data.crawl_stock_price_task manual__2024-06-01T00:46:54.511401+00:00 [queued]> finished (failed) although the task says it's queued. (Info: None) Was the task killed externally?
